Workbook
Name IQ_CH: 110000
Name IQ_CQ: 5000
Name IQ_CY: 10000
Name IQ_DAILY: 500000
Name IQ_FH: 100000
Name IQ_FQ: 500
Name IQ_FY: 1000
Name IQ_LTM: 2000
Name IQ_MONTH: 15000
Name IQ_NTM: 6000
Name IQ_WEEK: 50000
Name IQ_YTD: 3000

Sheet ConsolidatedResponses
A1: Supplier Name | B1: Source Language | C1: Service type | D1: Language | E1: Structure | F1: Release Platform | G1: Standard + Rate | H1: Standard Rate | I1: Batched Rate | J1: Rush Charge 1 | K1: Rush Charge 2 | L1: Additional Discount Offering Description | M1: % Discount Offered | N1: Notes / Additional Assumptions
A2: ='Summary (READ FIRST)'!$B$8 -> Supplier 1 | B2: ='Summary (READ FIRST)'!$B$11 -> English | C2: Subtitling | D2: Aymara | E2: FEATURE | F2: THEATRICAL RELEASE | G2: =Subtitling!E12 -> 26 | H2: =Subtitling!F12 -> 16 | J2: =Subtitling!$W$12 -> 1 | K2: =Subtitling!$X$12 -> 0.5 | L2: =Subtitling!$Z$12 -> Tools | M2: =Subtitling!$AA$12 -> 0.15 | N2: =Subtitling!$AB$12 -> Note 1
A3: ='Summary (READ FIRST)'!$B$8 -> Supplier 1 | B3: ='Summary (READ FIRST)'!$B$11 -> English | C3: Subtitling | D3: Aymara | E3: FEATURE | F3: NON-THEATRICAL - HOME ENT/STREAMING | G3: =Subtitling!H12 -> 28 | H3: =Subtitling!I12 -> 25 | J3: =Subtitling!$W$12 -> 1 | K3: =Subtitling!$X$12 -> 0.5 | L3: =Subtitling!$Z$12 -> Tools | M3: =Subtitling!$AA$12 -> 0.15 | N3: =Subtitling!$AB$12 -> Note 1
A4: ='Summary (READ FIRST)'!$B$8 -> Supplier 1 | B4: ='Summary (READ FIRST)'!$B$11 -> English | C4: Subtitling | D4: Aymara | E4: FEATURE | F4: NON-THEATRICAL - LINEAR BROADCAST | G4: =Subtitling!K12 -> 22 | H4: =Subtitling!L12 -> 10 | J4: =Subtitling!$W$12 -> 1 | K4: =Subtitling!$X$12 -> 0.5 | L4: =Subtitling!$Z$12 -> Tools | M4: =Subtitling!$AA$12 -> 0.15 | N4: =Subtitling!$AB$12 -> Note 1
A5: ='Summary (READ FIRST)'!$B$8 -> Supplier 1 | B5: ='Summary (READ FIRST)'!$B$11 -> English | C5: Subtitling | D5: Aymara | E5: EPISODIC | F5: HOME ENT/STREAMING | G5: =Subtitling!N12 -> 23 | H5: =Subtitling!O12 -> 17 | J5: =Subtitling!$W$12 -> 1 | K5: =Subtitling!$X$12 -> 0.5 | L5: =Subtitling!$Z$12 -> Tools | M5: =Subtitling!$AA$12 -> 0.15 | N5: =Subtitling!$AB$12 -> Note 1
A6: ='Summary (READ FIRST)'!$B$8 -> Supplier 1 | B6: ='Summary (READ FIRST)'!$B$11 -> English | C6: Subtitling | D6: Aymara | E6: EPISODIC | F6: BROADCAST/LINEAR | G6: =Subtitling!Q12 -> 34 | H6: =Subtitling!R12 -> 0 | J6: =Subtitling!$W$12 -> 1 | K6: =Subtitling!$X$12 -> 0.5 | L6: =Subtitling!$Z$12 -> Tools | M6: =Subtitling!$AA$12 -> 0.15 | N6: =Subtitling!$AB$12 -> Note 1
A7: ='Summary (READ FIRST)'!$B$8 -> Supplier 1 | B7: ='Summary (READ FIRST)'!$B$11 -> English | C7: Subtitling | D7: Aymara | E7: EPISODIC | F7: DISCOVERY/NON-SCRIPTED | G7: =Subtitling!T12 -> 19 | H7: =Subtitling!U12 -> 9 | J7: =Subtitling!$W$12 -> 1 | K7: =Subtitling!$X$12 -> 0.5 | L7: =Subtitling!$Z$12 -> Tools | M7: =Subtitling!$AA$12 -> 0.15 | N7: =Subtitling!$AB$12 -> Note 1
A8: ='Summary (READ FIRST)'!$B$8 -> Supplier 1 | B8: ='Summary (READ FIRST)'!$B$11 -> English | C8: Subtitling | D8: Mayan | E8: FEATURE | F8: THEATRICAL RELEASE | G8: =Subtitling!E13 -> 20 | H8: =Subtitling!F13 -> 8 | J8: =Subtitling!$W$13 -> 1 | K8: =Subtitling!$X$13 -> 0.5 | L8: =Subtitling!$Z$13 -> Workflow | M8: =Subtitling!$AA$13 -> 0 | N8: =Subtitling!$AB$13 -> 0
A9: ='Summary (READ FIRST)'!$B$8 -> Supplier 1 | B9: ='Summary (READ FIRST)'!$B$11 -> English | C9: Subtitling | D9: Mayan | E9: FEATURE | F9: NON-THEATRICAL - HOME ENT/STREAMING | G9: =Subtitling!H13 -> 21 | H9: =Subtitling!I13 -> 16 | J9: =Subtitling!$W$13 -> 1 | K9: =Subtitling!$X$13 -> 0.5 | L9: =Subtitling!$Z$13 -> Workflow | M9: =Subtitling!$AA$13 -> 0 | N9: =Subtitling!$AB$13 -> 0
A10: ='Summary (READ FIRST)'!$B$8 -> Supplier 1 | B10: ='Summary (READ FIRST)'!$B$11 -> English | C10: Subtitling | D10: Mayan | E10: FEATURE | F10: NON-THEATRICAL - LINEAR BROADCAST | G10: =Subtitling!K13 -> 0 | H10: =Subtitling!L13 -> 12 | J10: =Subtitling!$W$13 -> 1 | K10: =Subtitling!$X$13 -> 0.5 | L10: =Subtitling!$Z$13 -> Workflow | M10: =Subtitling!$AA$13 -> 0 | N10: =Subtitling!$AB$13 -> 0
A11: ='Summary (READ FIRST)'!$B$8 -> Supplier 1 | B11: ='Summary (READ FIRST)'!$B$11 -> English | C11: Subtitling | D11: Mayan | E11: EPISODIC | F11: HOME ENT/STREAMING | G11: =Subtitling!N13 -> 0 | H11: =Subtitling!O13 -> 17 | J11: =Subtitling!$W$13 -> 1 | K11: =Subtitling!$X$13 -> 0.5 | L11: =Subtitling!$Z$13 -> Workflow | M11: =Subtitling!$AA$13 -> 0 | N11: =Subtitling!$AB$13 -> 0
A12: ='Summary (READ FIRST)'!$B$8 -> Supplier 1 | B12: ='Summary (READ FIRST)'!$B$11 -> English | C12: Subtitling | D12: Mayan | E12: EPISODIC | F12: BROADCAST/LINEAR | G12: =Subtitling!Q13 -> 27 | H12: =Subtitling!R13 -> 20 | J12: =Subtitling!$W$13 -> 1 | K12: =Subtitling!$X$13 -> 0.5 | L12: =Subtitling!$Z$13 -> Workflow | M12: =Subtitling!$AA$13 -> 0 | N12: =Subtitling!$AB$13 -> 0
A13: ='Summary (READ FIRST)'!$B$8 -> Supplier 1 | B13: ='Summary (READ FIRST)'!$B$11 -> English | C13: Subtitling | D13: Mayan | E13: EPISODIC | F13: DISCOVERY/NON-SCRIPTED | G13: =Subtitling!T13 -> 0 | H13: =Subtitling!U13 -> 12 | J13: =Subtitling!$W$13 -> 1 | K13: =Subtitling!$X$13 -> 0.5 | L13: =Subtitling!$Z$13 -> Workflow | M13: =Subtitling!$AA$13 -> 0 | N13: =Subtitling!$AB$13 -> 0
A14: ='Summary (READ FIRST)'!$B$8 -> Supplier 1 | B14: ='Summary (READ FIRST)'!$B$11 -> English | C14: Subtitling | D14: Portuguese (Brazil) | E14: FEATURE | F14: THEATRICAL RELEASE | G14: =Subtitling!E14 -> 0 | H14: =Subtitling!F14 -> 21 | J14: =Subtitling!$W$14 -> 0 | K14: =Subtitling!$X$14 -> 0 | L14: =Subtitling!$Z$14 -> 0 | M14: =Subtitling!$AA$14 -> 0.2 | N14: =Subtitling!$AB$14 -> 0
A15: ='Summary (READ FIRST)'!$B$8 -> Supplier 1 | B15: ='Summary (READ FIRST)'!$B$11 -> English | C15: Subtitling | D15: Portuguese (Brazil) | E15: FEATURE | F15: NON-THEATRICAL - HOME ENT/STREAMING | G15: =Subtitling!H14 -> 27 | H15: =Subtitling!I14 -> 18 | J15: =Subtitling!$W$14 -> 0 | K15: =Subtitling!$X$14 -> 0 | L15: =Subtitling!$Z$14 -> 0 | M15: =Subtitling!$AA$14 -> 0.2 | N15: =Subtitling!$AB$14 -> 0
A16: ='Summary (READ FIRST)'!$B$8 -> Supplier 1 | B16: ='Summary (READ FIRST)'!$B$11 -> English | C16: Subtitling | D16: Portuguese (Brazil) | E16: FEATURE | F16: NON-THEATRICAL - LINEAR BROADCAST | G16: =Subtitling!K14 -> 38 | H16: =Subtitling!L14 -> 24 | J16: =Subtitling!$W$14 -> 0 | K16: =Subtitling!$X$14 -> 0 | L16: =Subtitling!$Z$14 -> 0 | M16: =Subtitling!$AA$14 -> 0.2 | N16: =Subtitling!$AB$14 -> 0
A17: ='Summary (READ FIRST)'!$B$8 -> Supplier 1 | B17: ='Summary (READ FIRST)'!$B$11 -> English | C17: Subtitling | D17: Portuguese (Brazil) | E17: EPISODIC | F17: HOME ENT/STREAMING | G17: =Subtitling!N14 -> 38 | H17: =Subtitling!O14 -> 21 | J17: =Subtitling!$W$14 -> 0 | K17: =Subtitling!$X$14 -> 0 | L17: =Subtitling!$Z$14 -> 0 | M17: =Subtitling!$AA$14 -> 0.2 | N17: =Subtitling!$AB$14 -> 0
A18: ='Summary (READ FIRST)'!$B$8 -> Supplier 1 | B18: ='Summary (READ FIRST)'!$B$11 -> English | C18: Subtitling | D18: Portuguese (Brazil) | E18: EPISODIC | F18: BROADCAST/LINEAR | G18: =Subtitling!Q14 -> 0 | H18: =Subtitling!R14 -> 19 | J18: =Subtitling!$W$14 -> 0 | K18: =Subtitling!$X$14 -> 0 | L18: =Subtitling!$Z$14 -> 0 | M18: =Subtitling!$AA$14 -> 0.2 | N18: =Subtitling!$AB$14 -> 0
A19: ='Summary (READ FIRST)'!$B$8 -> Supplier 1 | B19: ='Summary (READ FIRST)'!$B$11 -> English | C19: Subtitling | D19: Portuguese (Brazil) | E19: EPISODIC | F19: DISCOVERY/NON-SCRIPTED | G19: =Subtitling!T14 -> 21 | H19: =Subtitling!U14 -> 0 | J19: =Subtitling!$W$14 -> 0 | K19: =Subtitling!$X$14 -> 0 | L19: =Subtitling!$Z$14 -> 0 | M19: =Subtitling!$AA$14 -> 0.2 | N19: =Subtitling!$AB$14 -> 0
A20: ='Summary (READ FIRST)'!$B$8 -> Supplier 1 | B20: ='Summary (READ FIRST)'!$B$11 -> English | C20: Subtitling | D20: Quechua | E20: FEATURE | F20: THEATRICAL RELEASE | G20: =Subtitling!E15 -> 27 | H20: =Subtitling!F15 -> 22 | J20: =Subtitling!$W$15 -> 1 | K20: =Subtitling!$X$15 -> 0.5 | L20: =Subtitling!$Z$15 -> Tools | M20: =Subtitling!$AA$15 -> 0.05 | N20: =Subtitling!$AB$15 -> Note 1
A21: ='Summary (READ FIRST)'!$B$8 -> Supplier 1 | B21: ='Summary (READ FIRST)'!$B$11 -> English | C21: Subtitling | D21: Quechua | E21: FEATURE | F21: NON-THEATRICAL - HOME ENT/STREAMING | G21: =Subtitling!H15 -> 27 | H21: =Subtitling!I15 -> 23 | J21: =Subtitling!$W$15 -> 1 | K21: =Subtitling!$X$15 -> 0.5 | L21: =Subtitling!$Z$15 -> Tools | M21: =Subtitling!$AA$15 -> 0.05 | N21: =Subtitling!$AB$15 -> Note 1
A22: ='Summary (READ FIRST)'!$B$8 -> Supplier 1 | B22: ='Summary (READ FIRST)'!$B$11 -> English | C22: Subtitling | D22: Quechua | E22: FEATURE | F22: NON-THEATRICAL - LINEAR BROADCAST | G22: =Subtitling!K15 -> 36 | H22: =Subtitling!L15 -> 20 | J22: =Subtitling!$W$15 -> 1 | K22: =Subtitling!$X$15 -> 0.5 | L22: =Subtitling!$Z$15 -> Tools | M22: =Subtitling!$AA$15 -> 0.05 | N22: =Subtitling!$AB$15 -> Note 1
A23: ='Summary (READ FIRST)'!$B$8 -> Supplier 1 | B23: ='Summary (READ FIRST)'!$B$11 -> English | C23: Subtitling | D23: Quechua | E23: EPISODIC | F23: HOME ENT/STREAMING | G23: =Subtitling!N15 -> 0 | H23: =Subtitling!O15 -> 15 | J23: =Subtitling!$W$15 -> 1 | K23: =Subtitling!$X$15 -> 0.5 | L23: =Subtitling!$Z$15 -> Tools | M23: =Subtitling!$AA$15 -> 0.05 | N23: =Subtitling!$AB$15 -> Note 1
A24: ='Summary (READ FIRST)'!$B$8 -> Supplier 1 | B24: ='Summary (READ FIRST)'!$B$11 -> English | C24: Subtitling | D24: Quechua | E24: EPISODIC | F24: BROADCAST/LINEAR | G24: =Subtitling!Q15 -> 26 | H24: =Subtitling!R15 -> 15 | J24: =Subtitling!$W$15 -> 1 | K24: =Subtitling!$X$15 -> 0.5 | L24: =Subtitling!$Z$15 -> Tools | M24: =Subtitling!$AA$15 -> 0.05 | N24: =Subtitling!$AB$15 -> Note 1
A25: ='Summary (READ FIRST)'!$B$8 -> Supplier 1 | B25: ='Summary (READ FIRST)'!$B$11 -> English | C25: Subtitling | D25: Quechua | E25: EPISODIC | F25: DISCOVERY/NON-SCRIPTED | G25: =Subtitling!T15 -> 38 | H25: =Subtitling!U15 -> 12 | J25: =Subtitling!$W$15 -> 1 | K25: =Subtitling!$X$15 -> 0.5 | L25: =Subtitling!$Z$15 -> Tools | M25: =Subtitling!$AA$15 -> 0.05 | N25: =Subtitling!$AB$15 -> Note 1
A26: ='Summary (READ FIRST)'!$B$8 -> Supplier 1 | B26: ='Summary (READ FIRST)'!$B$11 -> English | C26: Subtitling | D26: Quechua (Bolivia) | E26: FEATURE | F26: THEATRICAL RELEASE | G26: =Subtitling!E16 -> 23 | H26: =Subtitling!F16 -> 0 | J26: =Subtitling!$W$16 -> 1 | K26: =Subtitling!$X$16 -> 0.5 | L26: =Subtitling!$Z$16 -> Automated system | M26: =Subtitling!$AA$16 -> 0.1 | N26: =Subtitling!$AB$16 -> 0
A27: ='Summary (READ FIRST)'!$B$8 -> Supplier 1 | B27: ='Summary (READ FIRST)'!$B$11 -> English | C27: Subtitling | D27: Quechua (Bolivia) | E27: FEATURE | F27: NON-THEATRICAL - HOME ENT/STREAMING | G27: =Subtitling!H16 -> 0 | H27: =Subtitling!I16 -> 25 | J27: =Subtitling!$W$16 -> 1 | K27: =Subtitling!$X$16 -> 0.5 | L27: =Subtitling!$Z$16 -> Automated system | M27: =Subtitling!$AA$16 -> 0.1 | N27: =Subtitling!$AB$16 -> 0
A28: ='Summary (READ FIRST)'!$B$8 -> Supplier 1 | B28: ='Summary (READ FIRST)'!$B$11 -> English | C28: Subtitling | D28: Quechua (Bolivia) | E28: FEATURE | F28: NON-THEATRICAL - LINEAR BROADCAST | G28: =Subtitling!K16 -> 20 | H28: =Subtitling!L16 -> 0 | J28: =Subtitling!$W$16 -> 1 | K28: =Subtitling!$X$16 -> 0.5 | L28: =Subtitling!$Z$16 -> Automated system | M28: =Subtitling!$AA$16 -> 0.1 | N28: =Subtitling!$AB$16 -> 0
A29: ='Summary (READ FIRST)'!$B$8 -> Supplier 1 | B29: ='Summary (READ FIRST)'!$B$11 -> English | C29: Subtitling | D29: Quechua (Bolivia) | E29: EPISODIC | F29: HOME ENT/STREAMING | G29: =Subtitling!N16 -> 16 | H29: =Subtitling!O16 -> 9 | J29: =Subtitling!$W$16 -> 1 | K29: =Subtitling!$X$16 -> 0.5 | L29: =Subtitling!$Z$16 -> Automated system | M29: =Subtitling!$AA$16 -> 0.1 | N29: =Subtitling!$AB$16 -> 0
A30: ='Summary (READ FIRST)'!$B$8 -> Supplier 1 | B30: ='Summary (READ FIRST)'!$B$11 -> English | C30: Subtitling | D30: Quechua (Bolivia) | E30: EPISODIC | F30: BROADCAST/LINEAR | G30: =Subtitling!Q16 -> 12 | H30: =Subtitling!R16 -> 8 | J30: =Subtitling!$W$16 -> 1 | K30: =Subtitling!$X$16 -> 0.5 | L30: =Subtitling!$Z$16 -> Automated system | M30: =Subtitling!$AA$16 -> 0.1 | N30: =Subtitling!$AB$16 -> 0
A31: ='Summary (READ FIRST)'!$B$8 -> Supplier 1 | B31: ='Summary (READ FIRST)'!$B$11 -> English | C31: Subtitling | D31: Quechua (Bolivia) | E31: EPISODIC | F31: DISCOVERY/NON-SCRIPTED | G31: =Subtitling!T16 -> 33 | H31: =Subtitling!U16 -> 21 | J31: =Subtitling!$W$16 -> 1 | K31: =Subtitling!$X$16 -> 0.5 | L31: =Subtitling!$Z$16 -> Automated system | M31: =Subtitling!$AA$16 -> 0.1 | N31: =Subtitling!$AB$16 -> 0
A32: ='Summary (READ FIRST)'!$B$8 -> Supplier 1 | B32: ='Summary (READ FIRST)'!$B$11 -> English | C32: Subtitling | D32: Quechua (Ecuador) | E32: FEATURE | F32: THEATRICAL RELEASE | G32: =Subtitling!E17 -> 40 | H32: =Subtitling!F17 -> 20 | J32: =Subtitling!$W$17 -> 1 | K32: =Subtitling!$X$17 -> 0.5 | L32: =Subtitling!$Z$17 -> Workflow | M32: =Subtitling!$AA$17 -> 0.1 | N32: =Subtitling!$AB$17 -> Note 1
A33: ='Summary (READ FIRST)'!$B$8 -> Supplier 1 | B33: ='Summary (READ FIRST)'!$B$11 -> English | C33: Subtitling | D33: Quechua (Ecuador) | E33: FEATURE | F33: NON-THEATRICAL - HOME ENT/STREAMING | G33: =Subtitling!H17 -> 20 | H33: =Subtitling!I17 -> 17 | J33: =Subtitling!$W$17 -> 1 | K33: =Subtitling!$X$17 -> 0.5 | L33: =Subtitling!$Z$17 -> Workflow | M33: =Subtitling!$AA$17 -> 0.1 | N33: =Subtitling!$AB$17 -> Note 1
A34: ='Summary (READ FIRST)'!$B$8 -> Supplier 1 | B34: ='Summary (READ FIRST)'!$B$11 -> English | C34: Subtitling | D34: Quechua (Ecuador) | E34: FEATURE | F34: NON-THEATRICAL - LINEAR BROADCAST | G34: =Subtitling!K17 -> 34 | H34: =Subtitling!L17 -> 18 | J34: =Subtitling!$W$17 -> 1 | K34: =Subtitling!$X$17 -> 0.5 | L34: =Subtitling!$Z$17 -> Workflow | M34: =Subtitling!$AA$17 -> 0.1 | N34: =Subtitling!$AB$17 -> Note 1
A35: ='Summary (READ FIRST)'!$B$8 -> Supplier 1 | B35: ='Summary (READ FIRST)'!$B$11 -> English | C35: Subtitling | D35: Quechua (Ecuador) | E35: EPISODIC | F35: HOME ENT/STREAMING | G35: =Subtitling!N17 -> 34 | H35: =Subtitling!O17 -> 0 | J35: =Subtitling!$W$17 -> 1 | K35: =Subtitling!$X$17 -> 0.5 | L35: =Subtitling!$Z$17 -> Workflow | M35: =Subtitling!$AA$17 -> 0.1 | N35: =Subtitling!$AB$17 -> Note 1
A36: ='Summary (READ FIRST)'!$B$8 -> Supplier 1 | B36: ='Summary (READ FIRST)'!$B$11 -> English | C36: Subtitling | D36: Quechua (Ecuador) | E36: EPISODIC | F36: BROADCAST/LINEAR | G36: =Subtitling!Q17 -> 0 | H36: =Subtitling!R17 -> 0 | J36: =Subtitling!$W$17 -> 1 | K36: =Subtitling!$X$17 -> 0.5 | L36: =Subtitling!$Z$17 -> Workflow | M36: =Subtitling!$AA$17 -> 0.1 | N36: =Subtitling!$AB$17 -> Note 1
A37: ='Summary (READ FIRST)'!$B$8 -> Supplier 1 | B37: ='Summary (READ FIRST)'!$B$11 -> English | C37: Subtitling | D37: Quechua (Ecuador) | E37: EPISODIC | F37: DISCOVERY/NON-SCRIPTED | G37: =Subtitling!T17 -> 0 | H37: =Subtitling!U17 -> 0 | J37: =Subtitling!$W$17 -> 1 | K37: =Subtitling!$X$17 -> 0.5 | L37: =Subtitling!$Z$17 -> Workflow | M37: =Subtitling!$AA$17 -> 0.1 | N37: =Subtitling!$AB$17 -> Note 1
A38: ='Summary (READ FIRST)'!$B$8 -> Supplier 1 | B38: ='Summary (READ FIRST)'!$B$11 -> English | C38: Subtitling | D38: Quechua (Peru) | E38: FEATURE | F38: THEATRICAL RELEASE | G38: =Subtitling!E18 -> 29 | H38: =Subtitling!F18 -> 25 | J38: =Subtitling!$W$18 -> 0 | K38: =Subtitling!$X$18 -> 0 | L38: =Subtitling!$Z$18 -> 0 | M38: =Subtitling!$AA$18 -> 0 | N38: =Subtitling!$AB$18 -> Note 1
A39: ='Summary (READ FIRST)'!$B$8 -> Supplier 1 | B39: ='Summary (READ FIRST)'!$B$11 -> English | C39: Subtitling | D39: Quechua (Peru) | E39: FEATURE | F39: NON-THEATRICAL - HOME ENT/STREAMING | G39: =Subtitling!H18 -> 37 | H39: =Subtitling!I18 -> 24 | J39: =Subtitling!$W$18 -> 0 | K39: =Subtitling!$X$18 -> 0 | L39: =Subtitling!$Z$18 -> 0 | M39: =Subtitling!$AA$18 -> 0 | N39: =Subtitling!$AB$18 -> Note 1
A40: ='Summary (READ FIRST)'!$B$8 -> Supplier 1 | B40: ='Summary (READ FIRST)'!$B$11 -> English | C40: Subtitling | D40: Quechua (Peru) | E40: FEATURE | F40: NON-THEATRICAL - LINEAR BROADCAST | G40: =Subtitling!K18 -> 25 | H40: =Subtitling!L18 -> 0 | J40: =Subtitling!$W$18 -> 0 | K40: =Subtitling!$X$18 -> 0 | L40: =Subtitling!$Z$18 -> 0 | M40: =Subtitling!$AA$18 -> 0 | N40: =Subtitling!$AB$18 -> Note 1
...

Sheet Summary (READ FIRST)
B2: WBD GCO Localization Long Form RFP
B3: Spring 2026
B5: Please fill out all fields in yellow before proceeding. Rates are to be shared in the subsequent tabs.
B7: Supplier name:
B8: Supplier 1
B10: Source language:
B11: English
B13: Assumptions
B14: 1. The source language is English unless otherwise noted. Vendors are welcome to submit rates for different source languages,
B15: but they must be submitted in separate copies of this file.
B16: 2. All rates are submitted in USD per minute.

Sheet Subtitling
C2: WBD GCO Localization RFP - MASTER Rate Card
C3: Please refer to the SLAs tab for detailed descriptions, definitions, and SLAs of each content type. Each section in the table is accompanied by a corresponding definitions table for clarity.
C4: Please provide a rate (USD) in the yellow cells.
E7: SUBTITLING SERVICES
E9: FEATURE | N9: EPISODIC
E10: THEATRICAL RELEASE | H10: NON-THEATRICAL - HOME ENT/STREAMING | K10: NON-THEATRICAL - LINEAR BROADCAST | N10: HOME ENT/STREAMING | Q10: BROADCAST/LINEAR | T10: DISCOVERY/NON-SCRIPTED | W10: Rush Charge 1 (%) | X10: Rush Charge 2 (%) | Z10: ADDITIONAL DISCOUNT OFFERING | AB10: Notes / Additional Assumptions
B11: No. | C11: Language | E11: Feature - Standard + | F11: Feature - Standard | H11: Feature - Standard + | I11: Feature - Standard | K11: Feature - Standard + | L11: Feature - Standard | N11: Episodic - Standard + | O11: Episodic - Standard | Q11: Episodic - Standard + | R11: Episodic - Standard | T11: Episodic - Standard + | U11: Episodic - Standard | W11: 1 day | X11: 2 days | Z11: Discount Offering Description - please provide additional discount offer based on use of any method that achieves efficiency and cost benefit (tools, workflow, etc). | AA11: % Discount Offered | AB11: Provide any additional information or assumptions
B12: 1 | C12: Aymara | E12: 26 | F12: 16 | H12: 28 | I12: 25 | K12: 22 | L12: 10 | N12: 23 | O12: 17 | Q12: 34 | T12: 19 | U12: 9 | W12: 1 | X12: 0.5 | Z12: Tools | AA12: 0.15 | AB12: Note 1
B13: 2 | C13: Mayan | E13: 20 | F13: 8 | H13: 21 | I13: 16 | L13: 12 | O13: 17 | Q13: 27 | R13: 20 | U13: 12 | W13: 1 | X13: 0.5 | Z13: Workflow
B14: 3 | C14: Portuguese (Brazil) | F14: 21 | H14: 27 | I14: 18 | K14: 38 | L14: 24 | N14: 38 | O14: 21 | R14: 19 | T14: 21 | AA14: 0.2
B15: 4 | C15: Quechua | E15: 27 | F15: 22 | H15: 27 | I15: 23 | K15: 36 | L15: 20 | O15: 15 | Q15: 26 | R15: 15 | T15: 38 | U15: 12 | W15: 1 | X15: 0.5 | Z15: Tools | AA15: 0.05 | AB15: Note 1
B16: 5 | C16: Quechua (Bolivia) | E16: 23 | I16: 25 | K16: 20 | N16: 16 | O16: 9 | Q16: 12 | R16: 8 | T16: 33 | U16: 21 | W16: 1 | X16: 0.5 | Z16: Automated system | AA16: 0.1
B17: 6 | C17: Quechua (Ecuador) | E17: 40 | F17: 20 | H17: 20 | I17: 17 | K17: 34 | L17: 18 | N17: 34 | W17: 1 | X17: 0.5 | Z17: Workflow | AA17: 0.1 | AB17: Note 1
B18: 7 | C18: Quechua (Peru) | E18: 29 | F18: 25 | H18: 37 | I18: 24 | K18: 25 | N18: 16 | O18: 13 | Q18: 40 | R18: 25 | T18: 27 | U18: 12 | AB18: Note 1
B19: 8 | C19: Spanish (Colombia) | F19: 22 | I19: 15 | K19: 35 | L19: 8 | O19: 8 | Q19: 21 | R19: 14 | T19: 23 | U19: 14 | W19: 1 | X19: 0.5 | Z19: Automated system | AA19: 0.2 | AB19: Note 1
B20: 9 | C20: Spanish (Mexico) | E20: 31 | H20: 39 | N20: 22 | O20: 15 | Q20: 33 | R20: 21 | U20: 21 | W20: 1 | X20: 0.5 | Z20: Tools | AA20: 0.05
B21: 10 | C21: Spanish (Latin American) | E21: 37 | F21: 23 | H21: 27 | I21: 19 | K21: 22 | L21: 14 | N21: 22 | Q21: 29 | T21: 26 | W21: 1 | X21: 0.5 | Z21: Workflow | AA21: 0.15 | AB21: Note 1
B22: 11 | C22: Zapotec | E22: 26 | F22: 18 | H22: 23 | I22: 17 | K22: 39 | L22: 19 | N22: 35 | O22: 22 | R22: 26 | T22: 20 | U22: 13 | W22: 1 | X22: 0.5 | Z22: Tools | AA22: 0.1 | AB22: Note 1

Sheet CC & HOH
C2: WBD GCO Localization RFP - MASTER Rate Card
C3: Please refer to the SLAs tab for detailed descriptions, definitions, and SLAs of each content type. Each section in the table is accompanied by a corresponding definitions table for clarity.
C4: Please provide a rate (USD) in the yellow cells.
E7: CC & HOH SERVICES
E9: FEATURE | N9: EPISODIC
E10: THEATRICAL RELEASE | H10: NON-THEATRICAL - HOME ENT/STREAMING | K10: NON-THEATRICAL - LINEAR BROADCAST | N10: HOME ENT/STREAMING | Q10: BROADCAST/LINEAR | T10: DISCOVERY/NON-SCRIPTED | W10: Rush Charge 1 (%) | X10: Rush Charge 2 (%) | Z10: ADDITIONAL DISCOUNT OFFERING | AB10: Notes / Additional Assumptions
B11: No. | C11: Language | E11: Feature - Standard + | F11: Feature - Standard | H11: Feature - Standard + | I11: Feature - Standard | K11: Feature - Standard + | L11: Feature - Standard | N11: Episodic - Standard + | O11: Episodic - Standard | Q11: Episodic - Standard + | R11: Episodic - Standard | T11: Episodic - Standard + | U11: Episodic - Standard | W11: 1 day | X11: 2 days | Z11: Discount Offering Description - please provide additional discount offer based on use of any method that achieves efficiency and cost benefit (tools, workflow, etc). | AA11: % Discount Offered | AB11: Provide any additional information or assumptions
B12: 1 | C12: Aymara | E12: 15 | F12: 7 | H12: 5 | I12: 4 | K12: 10 | L12: 9 | N12: 8 | O12: 3 | R12: 8 | T12: 12 | U12: 8 | W12: 1 | X12: 0.5 | Z12: Tools | AA12: 0.15 | AB12: Note 2
B13: 2 | C13: Mayan | E13: 17 | H13: 6 | K13: 11 | N13: 10 | O13: 6 | Q13: 12 | R13: 9 | T13: 8 | U13: 4 | X13: 0.5 | Z13: Workflow | AA13: 0.1 | AB13: Note 2
B14: 3 | C14: Portuguese (Brazil) | E14: 8 | F14: 3 | H14: 10 | I14: 4 | L14: 6 | N14: 13 | O14: 10 | Q14: 7 | U14: 8 | W14: 1 | X14: 0.5 | AA14: 0.05 | AB14: Note 2
B15: 4 | C15: Quechua | E15: 15 | F15: 10 | H15: 9 | I15: 7 | K15: 8 | L15: 7 | O15: 8 | Q15: 9 | R15: 5 | T15: 8 | U15: 6 | W15: 1 | X15: 0.5 | Z15: Tools
B16: 5 | C16: Quechua (Bolivia) | E16: 14 | F16: 9 | I16: 7 | K16: 9 | L16: 4 | N16: 11 | O16: 7 | Q16: 6 | R16: 3 | T16: 9 | U16: 7 | W16: 1 | Z16: Automated system | AA16: 0.1 | AB16: Note 2
B17: 6 | C17: Quechua (Ecuador) | F17: 4 | H17: 11 | I17: 6 | K17: 9 | L17: 6 | N17: 9 | O17: 7 | Q17: 8 | R17: 5 | T17: 9 | W17: 1 | X17: 0.5 | Z17: Workflow | AA17: 0.1 | AB17: Note 2
B18: 7 | C18: Quechua (Peru) | E18: 9 | F18: 8 | H18: 14 | I18: 3 | K18: 10 | N18: 11 | R18: 10 | T18: 5 | U18: 3 | W18: 1 | X18: 0.5 | Z18: Workflow | AB18: Note 2
B19: 8 | C19: Spanish (Colombia) | E19: 5 | F19: 3 | H19: 9 | I19: 6 | K19: 9 | L19: 7 | N19: 9 | O19: 5 | Q19: 15 | R19: 12 | T19: 9 | U19: 8 | W19: 1 | X19: 0.5 | AA19: 0.05
B20: 10 | C20: Spanish (Mexico) | E20: 5 | H20: 10 | I20: 4 | K20: 11 | L20: 8 | N20: 12 | O20: 7 | R20: 10 | U20: 10 | W20: 1 | X20: 0.5 | Z20: Tools | AA20: 0.05 | AB20: Note 2
B21: 11 | C21: Spanish (Latin American) | E21: 10 | F21: 8 | H21: 9 | L21: 5 | O21: 7 | Q21: 14 | R21: 8 | T21: 10 | U21: 5 | W21: 1 | X21: 0.5 | Z21: Workflow | AA21: 0.15 | AB21: Note 2
B22: 12 | C22: Zapotec | E22: 11 | F22: 10 | H22: 15 | I22: 9 | K22: 13 | L22: 5 | N22: 15 | O22: 8 | Q22: 8 | R22: 7 | T22: 15 | U22: 7 | X22: 0.5 | Z22: Tools | AA22: 0.1 | AB22: Note 2

Sheet Dubbing
C2: WBD GCO Localization RFP - MASTER Rate Card
C3: Please refer to the SLAs tab for detailed descriptions, definitions, and SLAs of each content type. Each section in the table is accompanied by a corresponding definitions table for clarity.
C4: Please provide a rate (USD) in the yellow cells.
E7: DUBBING SERVICES
E9: FEATURE | T9: EPISODIC
E10: THEATRICAL RELEASE | J10: NON-THEATRICAL | O10: NON-THEATRICAL - LINEAR BROADCAST | T10: EPISODIC SERIES | AA10: DISCOVERY/NON-SCRIPTED | AE10: Rush Charge 1 (%) | AF10: Rush Charge 2 (%) | AH10: ADDITIONAL DISCOUNT OFFERING | AJ10: Notes / Additional Assumptions
B11: No. | C11: Language | E11: Feature - Standard + DUBBING | F11: Feature - Standard + MIXING | G11: Feature - Standard DUBBING | H11: Feature - Standard MIXING | J11: Feature - Standard + DUBBING | K11: Feature - Standard + MIXING | L11: Feature - Standard DUBBING | M11: Feature - Standard MIXING | O11: Feature - Standard + DUBBING | P11: Feature - Standard + MIXING | Q11: Feature - Standard DUBBING | R11: Feature - Standard MIXING | T11: Single Episode - Standard + DUBBING | U11: Single Episode - Standard + MIXING | V11: Single Episode - Standard DUBBING | W11: Single Episode - Standard MIXING | X11: Full Series or Batched Episodes DUBBING | Y11: Full Series or Batched Episodes MIXING | AA11: Single Episode - Standard + | AB11: Single Episode - Standard | AC11: Full Series or Batched Episodes | AE11: 1 day | AF11: 2 days | AH11: Discount Offering Description - please provide additional discount offer based on use of any method that achieves efficiency and cost benefit (tools, workflow, etc). | AI11: % Discount Offered | AJ11: Provide any additional information or assumptions
B12: 1 | C12: Aymara | E12: 80 | F12: 70 | G12: 59 | H12: 51 | J12: 95 | K12: 89 | L12: 55 | M12: 33 | O12: 79 | P12: 71 | Q12: 69 | R12: 50 | T12: 71 | U12: 57 | V12: 60 | W12: 56 | X12: 63 | Y12: 69 | AA12: 56 | AB12: 55 | AC12: 84 | AE12: 1 | AF12: 0.5 | AH12: Tools | AI12: 0.15 | AJ12: Note 3
B13: 2 | C13: Mayan | E13: 81 | G13: 50 | H13: 50 | J13: 111 | K13: 118 | L13: 25 | M13: 72 | O13: 65 | P13: 55 | Q13: 54 | U13: 64 | V13: 74 | X13: 87 | AB13: 56 | AE13: 1 | AF13: 0.5 | AH13: Workflow | AI13: 0.1 | AJ13: Note 3
B14: 3 | C14: Portuguese (Brazil) | E14: 62 | F14: 114 | L14: 78 | M14: 63 | O14: 62 | P14: 96 | Q14: 56 | R14: 34 | T14: 90 | U14: 102 | W14: 56 | X14: 53 | Y14: 106 | AA14: 104 | AB14: 28 | AC14: 98 | AF14: 0.5 | AH14: Automated system | AI14: 0.2 | AJ14: Note 3
B15: 4 | C15: Quechua | G15: 35 | H15: 66 | J15: 54 | K15: 108 | L15: 27 | M15: 56 | Q15: 37 | R15: 55 | T15: 91 | U15: 64 | V15: 76 | W15: 52 | X15: 90 | Y15: 62 | AA15: 101 | AB15: 40 | AC15: 78 | AE15: 1 | AF15: 0.5
B16: 5 | C16: Quechua (Bolivia) | E16: 51 | F16: 50 | G16: 54 | H16: 37 | J16: 78 | K16: 119 | L16: 29 | O16: 70 | P16: 87 | Q16: 63 | R16: 69 | T16: 85 | U16: 119 | V16: 74 | Y16: 90 | AA16: 117 | AC16: 103 | AE16: 1 | AH16: Automated system | AI16: 0.1 | AJ16: Note 3
B17: 6 | C17: Quechua (Ecuador) | F17: 54 | G17: 67 | J17: 105 | M17: 34 | O17: 73 | P17: 82 | Q17: 70 | T17: 119 | W17: 45 | X17: 89 | AA17: 66 | AB17: 33 | AC17: 92 | AF17: 0.5 | AH17: Workflow | AI17: 0.1 | AJ17: Note 3
B18: 7 | C18: Quechua (Peru) | E18: 111 | H18: 25 | K18: 90 | L18: 37 | Q18: 56 | R18: 70 | T18: 110 | U18: 56 | V18: 38 | W18: 74 | X18: 52 | Y18: 92 | AB18: 25 | AC18: 111 | AE18: 1 | AF18: 0.5 | AH18: Workflow | AI18: 0.15
B19: 8 | C19: Spanish (Colombia) | F19: 56 | G19: 65 | J19: 73 | K19: 104 | L19: 50 | M19: 25 | O19: 119 | P19: 80 | Q19: 77 | R19: 42 | U19: 67 | V19: 60 | Y19: 103 | AA19: 98 | AB19: 77 | AE19: 1 | AJ19: Note 3
B20: 10 | C20: Spanish (Mexico) | E20: 89 | F20: 71 | H20: 68 | L20: 42 | M20: 77 | O20: 73 | P20: 82 | R20: 76 | T20: 120 | U20: 99 | V20: 79 | W20: 69 | X20: 83 | Y20: 99 | AA20: 53 | AB20: 33 | AC20: 95 | AE20: 1 | AF20: 0.5 | AH20: Tools | AI20: 0.05 | AJ20: Note 3
B21: 11 | C21: Spanish (Latin American) | G21: 68 | H21: 70 | J21: 59 | K21: 78 | P21: 89 | Q21: 27 | R21: 58 | T21: 95 | X21: 115 | AC21: 113 | AF21: 0.5 | AH21: Workflow | AI21: 0.15 | AJ21: Note 3
B22: 12 | C22: Zapotec | E22: 56 | F22: 61 | G22: 28 | H22: 75 | J22: 79 | K22: 54 | L22: 76 | M22: 46 | O22: 111 | P22: 119 | R22: 60 | T22: 102 | U22: 59 | V22: 49 | W22: 72 | X22: 59 | Y22: 59 | AA22: 77 | AB22: 66 | AC22: 109 | AE22: 1 | AF22: 0.5 | AH22: Tools | AI22: 0.1 | AJ22: Note 3

Sheet Audio Desc.
C2: WBD GCO Localization RFP - MASTER Rate Card
C3: Please refer to the SLAs tab for detailed descriptions, definitions, and SLAs of each content type. Each section in the table is accompanied by a corresponding definitions table for clarity.
C4: Please provide a rate (USD) in the yellow cells.
E7: AUDIO DESCRIPTION SERVICES
E9: FEATURE | T9: EPISODIC
E10: THEATRICAL RELEASE | J10: NON-THEATRICAL | O10: NON-THEATRICAL - LINEAR BROADCAST | T10: EPISODIC SERIES | AA10: DISCOVERY/NON-SCRIPTED | AE10: Rush Charge 1 (%) | AF10: Rush Charge 2 (%) | AH10: ADDITIONAL DISCOUNT OFFERING | AJ10: Notes / Additional Assumptions
B11: No. | C11: Language | E11: Feature - Standard + DUBBING | F11: Feature - Standard + MIXING | G11: Feature - Standard DUBBING | H11: Feature - Standard MIXING | J11: Feature - Standard + DUBBING | K11: Feature - Standard + MIXING | L11: Feature - Standard DUBBING | M11: Feature - Standard MIXING | O11: Feature - Standard + DUBBING | P11: Feature - Standard + MIXING | Q11: Feature - Standard DUBBING | R11: Feature - Standard MIXING | T11: Single Episode - Standard + DUBBING | U11: Single Episode - Standard + MIXING | V11: Single Episode - Standard DUBBING | W11: Single Episode - Standard MIXING | X11: Full Series or Batched Episodes DUBBING | Y11: Full Series or Batched Episodes MIXING | AA11: Single Episode - Standard + | AB11: Single Episode - Standard | AC11: Full Series or Batched Episodes | AE11: 1 day | AF11: 2 days | AH11: Discount Offering Description - please provide additional discount offer based on use of any method that achieves efficiency and cost benefit (tools, workflow, etc). | AI11: % Discount Offered | AJ11: Provide any additional information or assumptions
B12: 1 | C12: Aymara | E12: 86 | F12: 85 | G12: 26 | H12: 17 | J12: 43 | K12: 83 | L12: 16 | M12: 17 | O12: 42 | P12: 79 | Q12: 52 | R12: 15 | T12: 85 | U12: 93 | V12: 60 | W12: 49 | X12: 96 | Y12: 34 | AA12: 61 | AB12: 33 | AC12: 48 | AE12: 1 | AF12: 0.5 | AH12: Tools | AI12: 0.15 | AJ12: Note 4
B13: 2 | C13: Mayan | E13: 86 | F13: 44 | G13: 55 | H13: 36 | J13: 82 | K13: 47 | L13: 17 | M13: 86 | O13: 17 | P13: 45 | Q13: 94 | R13: 71 | T13: 43 | U13: 96 | V13: 36 | W13: 44 | X13: 90 | Y13: 83 | AA13: 69 | AB13: 52 | AC13: 55 | AE13: 1 | AF13: 0.5 | AI13: 0.1 | AJ13: Note 4
B14: 3 | C14: Portuguese (Brazil) | E14: 37 | G14: 17 | H14: 29 | J14: 50 | K14: 44 | L14: 23 | O14: 20 | Q14: 69 | R14: 96 | T14: 30 | U14: 60 | V14: 95 | AA14: 91 | AB14: 31 | AF14: 0.5 | AH14: Automated system | AJ14: Note 4
B15: 4 | C15: Quechua | E15: 87 | F15: 48 | G15: 59 | H15: 56 | J15: 82 | K15: 43 | M15: 68 | O15: 43 | P15: 30 | Q15: 69 | T15: 46 | W15: 79 | X15: 98 | Y15: 62 | AB15: 37 | AC15: 92 | AE15: 1 | AF15: 0.5 | AH15: Tools | AI15: 0.05 | AJ15: Note 4
B16: 5 | C16: Quechua (Bolivia) | E16: 80 | F16: 77 | G16: 56 | H16: 48 | L16: 15 | M16: 83 | O16: 31 | P16: 57 | Q16: 98 | R16: 81 | T16: 53 | U16: 85 | V16: 37 | X16: 70 | AA16: 88 | AB16: 47 | AC16: 53 | AE16: 1 | AI16: 0.1 | AJ16: Note 4
B17: 6 | C17: Quechua (Ecuador) | E17: 36 | F17: 92 | H17: 26 | J17: 52 | K17: 45 | L17: 32 | M17: 71 | O17: 27 | P17: 18 | R17: 84 | V17: 85 | W17: 50 | X17: 92 | Y17: 53 | AA17: 76 | AF17: 0.5 | AH17: Workflow
B18: 7 | C18: Quechua (Peru) | G18: 26 | H18: 49 | J18: 88 | K18: 38 | L18: 57 | M18: 88 | O18: 35 | P18: 29 | Q18: 59 | R18: 61 | T18: 31 | U18: 32 | V18: 76 | W18: 59 | X18: 43 | Y18: 65 | AA18: 40 | AB18: 34 | AC18: 99 | AE18: 1 | AF18: 0.5 | AH18: Workflow | AI18: 0.15 | AJ18: Note 4
B19: 8 | C19: Spanish (Colombia) | E19: 50 | F19: 86 | G19: 58 | H19: 20 | J19: 80 | K19: 43 | L19: 60 | M19: 98 | P19: 35 | Q19: 87 | U19: 49 | V19: 57 | W19: 38 | X19: 44 | AB19: 42 | AC19: 30 | AE19: 1 | AH19: Automated system | AI19: 0.2 | AJ19: Note 4
B20: 10 | C20: Spanish (Mexico) | E20: 55 | F20: 99 | G20: 17 | H20: 44 | O20: 52 | P20: 50 | Q20: 71 | R20: 50 | T20: 33 | X20: 37 | Y20: 91 | AA20: 78 | AB20: 57 | AF20: 0.5 | AJ20: Note 4
B21: 11 | C21: Spanish (Latin American) | E21: 72 | F21: 32 | G21: 31 | J21: 99 | K21: 40 | L21: 49 | M21: 90 | O21: 39 | P21: 19 | R21: 32 | T21: 55 | U21: 71 | V21: 91 | W21: 66 | X21: 85 | Y21: 77 | AA21: 68 | AB21: 37 | AC21: 87 | AE21: 1 | AF21: 0.5 | AH21: Workflow | AI21: 0.15
B22: 12 | C22: Zapotec | E22: 48 | F22: 81 | G22: 40 | H22: 38 | J22: 74 | K22: 23 | L22: 20 | M22: 50 | O22: 22 | P22: 20 | Q22: 64 | R22: 35 | T22: 18 | U22: 100 | V22: 56 | W22: 92 | X22: 95 | Y22: 44 | AA22: 55 | AB22: 52 | AC22: 71 | AE22: 1 | AH22: Tools | AI22: 0.1 | AJ22: Note 4

Sheet VO
C2: WBD GCO Localization RFP - MASTER Rate Card
C3: Please refer to the SLAs tab for detailed descriptions, definitions, and SLAs of each content type. Each section in the table is accompanied by a corresponding definitions table for clarity.
C4: Please provide a rate (USD) in the yellow cells.
E7: VOICEOVER SERVICES
E9: FEATURE | T9: EPISODIC
E10: LIMITED THEATRICAL | J10: NON-THEATRICAL | O10: NON-THEATRICAL - LINEAR BROADCAST | T10: EPISODIC SERIES | AA10: DISCOVERY/NON-SCRIPTED | AE10: Rush Charge 1 (%) | AF10: Rush Charge 2 (%) | AH10: ADDITIONAL DISCOUNT OFFERING | AJ10: Notes / Additional Assumptions
B11: No. | C11: Language | E11: Feature - Standard + DUBBING | F11: Feature - Standard + MIXING | G11: Feature - Standard DUBBING | H11: Feature - Standard MIXING | J11: Feature - Standard + DUBBING | K11: Feature - Standard + MIXING | L11: Feature - Standard DUBBING | M11: Feature - Standard MIXING | O11: Feature - Standard + DUBBING | P11: Feature - Standard + MIXING | Q11: Feature - Standard DUBBING | R11: Feature - Standard MIXING | T11: Single Episode - Standard + DUBBING | U11: Single Episode - Standard + MIXING | V11: Single Episode - Standard DUBBING | W11: Single Episode - Standard MIXING | X11: Full Series or Batched Episodes DUBBING | Y11: Full Series or Batched Episodes MIXING | AA11: Single Episode - Standard + | AB11: Single Episode - Standard | AC11: Full Series or Batched Episodes | AE11: 1 day | AF11: 2 days | AH11: Discount Offering Description - please provide additional discount offer based on use of any method that achieves efficiency and cost benefit (tools, workflow, etc). | AI11: % Discount Offered | AJ11: Provide any additional information or assumptions
B12: 1 | C12: Aymara | E12: 41 | F12: 57 | G12: 29 | H12: 40 | J12: 59 | K12: 60 | L12: 44 | M12: 30 | O12: 42 | P12: 45 | Q12: 34 | R12: 46 | T12: 41 | U12: 60 | V12: 24 | W12: 30 | X12: 57 | Y12: 45 | AA12: 67 | AB12: 43 | AC12: 39 | AE12: 1 | AF12: 0.5 | AH12: Tools | AI12: 0.15 | AJ12: Note 5
B13: 2 | C13: Mayan | E13: 41 | F13: 54 | K13: 47 | M13: 53 | O13: 56 | P13: 50 | R13: 29 | T13: 48 | U13: 41 | V13: 40 | W13: 34 | X13: 78 | Y13: 79 | AB13: 41 | AC13: 73 | AE13: 1 | AF13: 0.5 | AH13: Workflow | AI13: 0.1 | AJ13: Note 5
B14: 3 | C14: Portuguese (Brazil) | E14: 47 | F14: 54 | G14: 56 | H14: 20 | J14: 43 | K14: 35 | L14: 32 | M14: 22 | P14: 71 | Q14: 49 | R14: 20 | U14: 45 | W14: 60 | AA14: 30 | AC14: 73 | AE14: 1 | AF14: 0.5 | AI14: 0.2 | AJ14: Note 5
B15: 4 | C15: Quechua | E15: 53 | F15: 37 | G15: 59 | H15: 27 | J15: 37 | L15: 34 | M15: 46 | O15: 71 | P15: 69 | Q15: 53 | R15: 33 | T15: 55 | V15: 23 | W15: 39 | X15: 66 | Y15: 36 | AA15: 31 | AB15: 32 | AC15: 55 | AH15: Tools | AI15: 0.05
B16: 5 | C16: Quechua (Bolivia) | E16: 79 | G16: 51 | H16: 32 | J16: 46 | K16: 36 | L16: 24 | O16: 45 | Q16: 59 | U16: 62 | V16: 41 | X16: 44 | AA16: 63 | AB16: 24 | AE16: 1 | AF16: 0.5 | AH16: Automated system | AJ16: Note 5
B17: 6 | C17: Quechua (Ecuador) | F17: 52 | G17: 42 | K17: 73 | M17: 54 | O17: 53 | P17: 74 | Q17: 23 | R17: 32 | T17: 39 | U17: 77 | V17: 31 | W17: 50 | X17: 53 | Y17: 50 | AA17: 73 | AB17: 55 | AC17: 58 | AE17: 1 | AF17: 0.5 | AI17: 0.1 | AJ17: Note 5
B18: 7 | C18: Quechua (Peru) | E18: 77 | F18: 49 | G18: 25 | H18: 41 | J18: 55 | K18: 46 | L18: 36 | M18: 46 | P18: 59 | Q18: 29 | R18: 43 | T18: 40 | U18: 62 | V18: 25 | W18: 56 | Y18: 32 | AA18: 61 | AC18: 62 | AH18: Workflow | AI18: 0.15 | AJ18: Note 5
B19: 8 | C19: Spanish (Colombia) | E19: 73 | H19: 39 | J19: 58 | L19: 50 | O19: 77 | P19: 57 | R19: 28 | T19: 51 | W19: 37 | X19: 33 | Y19: 37 | AA19: 60 | AB19: 27 | AC19: 55 | AE19: 1 | AF19: 0.5 | AH19: Automated system | AI19: 0.2 | AJ19: Note 5
B20: 10 | C20: Spanish (Mexico) | E20: 62 | F20: 42 | G20: 21 | J20: 46 | K20: 53 | L20: 23 | M20: 29 | O20: 37 | Q20: 27 | R20: 27 | T20: 50 | U20: 45 | V20: 54 | W20: 43 | X20: 78 | AB20: 34 | AC20: 40 | AE20: 1
B21: 11 | C21: Spanish (Latin American) | E21: 50 | F21: 46 | G21: 27 | H21: 21 | K21: 54 | P21: 58 | Q21: 46 | U21: 75 | V21: 43 | W21: 29 | Y21: 51 | AA21: 68 | AB21: 59 | AF21: 0.5 | AH21: Workflow | AI21: 0.15 | AJ21: Note 5
B22: 12 | C22: Zapotec | E22: 51 | F22: 76 | G22: 50 | H22: 44 | J22: 43 | L22: 33 | M22: 42 | O22: 57 | P22: 45 | Q22: 30 | R22: 59 | T22: 69 | U22: 60 | V22: 37 | W22: 37 | X22: 74 | Y22: 51 | AA22: 70 | AB22: 28 | AC22: 69 | AE22: 1 | AF22: 0.5 | AH22: Tools | AI22: 0.1 | AJ22: Note 5

Sheet SLAs and Definitions >>
B2: This page intentionally left blank.

Sheet SLAs
B2: WBD GCO Localization RFP - SLAs
B3: Below are the correlating SLAs for each requested service. There are a total of 5 tables - Subtitilng, CC&HOH, Dubbing, Audio Description, and Voiceover.
B7: SUBTITLING SERVICES
D10: FEATURE | J10: EPISODIC
C11: Type of work | D11: THEATRICAL | F11: ALL CONTENT TYPES - HOME ENT/STREAMING Home Entertainment, Broadcast, SVOD, VOD… | H11: ALL CONTENT TYPES - LINEAR/BROADCAST Linear Broadcast Servicing Channel. | J11: ALL CONTENT TYPES - HOME ENT/STREAMING Home Entertainment, Broadcast, SVOD, VOD… | L11: ALL CONTENT TYPES - LINEAR/BROADCAST Linear Broadcast servicing Channel | N11: DISCOVERY / NON-SCRIPTED
C12: SLA | D12: Standard+ | E12: Standard | F12: Standard+ | G12: Standard | H12: Standard + | I12: Standard | J12: Standard + | K12: Standard | L12: Standard + | M12: Standard | N12: Standard + | O12: Standard
C13: Turnaround Time in Calendar Days - Final Materials to vendor and Localized Content Delivery | D13: 6-9 days for Feature | E13: ≥ 28 days for Feature | F13: 6-9 days for Feature | G13: ≥ 10 days for Feature | H13: 6 - 10 calendar days | I13: ≥ 11 calendar days | J13: 3-5 calendar days for Episodic (from final) | K13: ≥ 6 calendar days for Episodic (Half Hour) | L13: 3- 9 calendar days | M13: ≥ 10 calendar days | N13: 3-13 calendar days | O13: ≥ 14 calendar days
B14: Localization Function | C14: Activity | D14: Warner Bros. Discovery Consolidated Subtitling Rates Cards are based on the below service requirements
B15: SOURCE MATERIALS SUPPLIED FROM CLIENT | C15: Audio & Visual Content Prelim (Network, Locked) or Final (Low-Res or HD digital file; no physical) | D15: Locked Prelim and Final AV Materials (Note - addtional iterations can be can be provided by client if required) | E15: Final AV Materials | F15: Prelim (if required) and Final AV Materials | G15: Final AV Materials | H15: Prelim (if required) and Final AV Materials | I15: Final AV Materials | J15: Prelim (if required) and Final AV Materials | K15: Final AV Materials | L15: Prelim (if required) and Final AV Materials | M15: Final AV Materials | N15: Prelim (if required) and Final AV Materials | O15: Final AV Materials
C16: Scripts & Creative Documentation: Original Version Language (Ref Source Materials Definition Tab) | D16: Client to provide. If no English script or equivalent provided, additional charge may apply | E16: Client to provide. If no English script or equivalent provided, additional charge may apply | F16: Client to provide. If no English script or equivalent provided, additional charge may apply | G16: Client to provide. If no English script or equivalent provided, additional charge may apply | H16: Client to provide. If no English script or equivalent provided, additional charge may apply | I16: Client to provide. If no English script or equivalent provided, additional charge may apply | J16: Client to provide. If no English script or equivalent provided, additional charge may apply | K16: Client to provide. If no English script or equivalent provided, additional charge may apply | L16: Client to provide. If no English script or equivalent provided, additional charge may apply | M16: Client to provide. If no English script or equivalent provided, additional charge may apply | N16: Client to provide. If no English script or equivalent provided, additional charge may apply | O16: Client to provide. If no English script or equivalent provided, additional charge may apply
C17: Final Video Master When Video Master deliverable required | D17: Client to provide error free final video & audio, balanced M&E, textless at tail (if needed). Vendor to perform 3-point check QC upon receipt, noting issues within 48 hours | E17: Client to provide error free final video & audio, balanced M&E, textless at tail (if needed). Vendor to perform 3-point check QC upon receipt, noting issues within 48 hours | F17: Client to provide error free final video & audio, balanced M&E, textless at tail (if needed). Vendor to perform 3-point check QC upon receipt, noting issues within 48 hours | G17: Client to provide error free final video & audio, balanced M&E, textless at tail (if needed). Vendor to perform 3-point check QC upon receipt, noting issues within 48 hours | H17: Client to provide error free final video & audio, balanced M&E, textless at tail (if needed). Vendor to perform 3-point check QC upon receipt, noting issues within 48 hours | I17: Client to provide error free final video & audio, balanced M&E, textless at tail (if needed). Vendor to perform 3-point check QC upon receipt, noting issues within 48 hours | J17: Client to provide error free final video & audio, balanced M&E, textless at tail (if needed). Vendor to perform 3-point check QC upon receipt, noting issues within 48 hours | K17: Client to provide error free final video & audio, balanced M&E, textless at tail (if needed). Vendor to perform 3-point check QC upon receipt, noting issues within 48 hours | L17: Client to provide error free final video & audio, balanced M&E, textless at tail (if needed). Vendor to perform 3-point check QC upon receipt, noting issues within 48 hours | M17: Client to provide error free final video & audio, balanced M&E, textless at tail (if needed). Vendor to perform 3-point check QC upon receipt, noting issues within 48 hours | N17: Client to provide error free final video & audio Vendor to perform 3-point check QC upon receipt, noting issues within 48 hours | O17: Client to provide error free final video & audio Vendor to perform 3-point check QC upon receipt, noting issues within 48 hours
B18: SECURITY TIERS | C18: Applying security measures to Reference Materials (Ref Security Tiers Definition Tab) | D18: Tier MAX or 0. If Tier MAX required, additional charge may apply (security level to be discussed with client on each title) | E18: Tier MAX or 0. If Tier MAX required, additional charge may apply (security level to be discussed with client on each title) | F18: Vendor to provide secure access for translators / approvers to subtitling SaaS Platform. Additional watermarking must be applied by the system to ensure access is traceable to those granted access. | G18: Vendor to provide secure access for translators / approvers to subtitling SaaS Platform. Additional watermarking must be applied by the system to ensure access is traceable to those granted access. | H18: Vendor to provide secure access for translators / approvers to subtitling SaaS Platform. Additional watermarking must be applied by the system to ensure access is traceable to those granted access. | I18: Vendor to provide secure access for translators / approvers to subtitling SaaS Platform. Additional watermarking must be applied by the system to ensure access is traceable to those granted access. | J18: Vendor to provide secure access for translators / approvers to subtitling SaaS Platform. Additional watermarking must be applied by the system to ensure access is traceable to those granted access. | K18: Vendor to provide secure access for translators / approvers to subtitling SaaS Platform. Additional watermarking must be applied by the system to ensure access is traceable to those granted access. | L18: Vendor to provide secure access for translators / approvers to subtitling SaaS Platform. Additional watermarking must be applied by the system to ensure access is traceable to those granted access. | M18: Vendor to provide secure access for translators / approvers to subtitling SaaS Platform. Additional watermarking must be applied by the system to ensure access is traceable to those granted access. | N18: Vendor to provide secure access for translators / approvers to subtitling SaaS Platform. Additional watermarking must be applied by the system to ensure access is traceable to those granted access. | O18: Vendor to provide secure access for translators / approvers to subtitling SaaS Platform. Additional watermarking must be applied by the system to ensure access is traceable to those granted access.
B19: TRANSLATION | C19: Translator selection | D19: Client Translator selection. If vendor translator is required to ensure native speaker translator. | E19: Client Translator selection. If vendor translator is required to ensure native speaker translator. | F19: Vendor responsible for providing Native Speaker translator, client reserves the right to participate in translator selection. | G19: Vendor responsible for providing Native Speaker translator, client reserves the right to participate in translator selection | H19: Vendor responsible for providing Native Speaker translator. | I19: Vendor responsible for providing Native Speaker translator. | J19: Vendor responsible for providing Native Speaker translator, client reserves the right to participate in translator selection. | K19: Vendor responsible for providing Native Speaker translator, client reserves the right to participate in translator selection | L19: Vendor responsible for providing Native Speaker translator. | M19: Vendor responsible for providing Native Speaker translator. | N19: Vendor responsible for providing Native Speaker translator. | O19: Vendor responsible for providing Native Speaker translator.
C20: Linguistic & Technical QC | D20: Native Speaker Linguistic QC & Full Technical QC included. Changes to be approved by client translator/approver | E20: Native Speaker Linguistic QC & Full Technical QC included. Changes to be approved by client translator/approver | F20: Native Speaker Linguistic QC & Full Linear Technical QC included. | G20: Native Speaker Linguistic QC & Full Linear Technical QC included. | H20: Linguistic QC possible at additional charge. Technical QC included | I20: Linguistic QC possible at additional charge. Technical QC included | J20: Native Speaker Linguistic QC & Full Linear Technical QC included. | K20: Native Speaker Linguistic QC & Full Linear Technical QC included. | L20: Linguistic QC possible at additional charge. Technical QC included | M20: Linguistic QC possible at additional charge. Technical QC included | N20: Linguistic QC possible at additional charge. Technical QC included | O20: Linguistic QC possible at additional charge. Technical QC included
C21: Compliance | D21: Censorship and / or softening of language for certain content may be required. Any potential sensitivities must be flagged to client, especially children's content. | E21: Censorship and / or softening of language for certain content may be required. Any potential sensitivities must be flagged to client, especially children's content. | F21: Censorship and / or softening of language for certain content may be required. Any potential sensitivities must be flagged to client, especially children's content. | G21: Censorship and / or softening of language for certain content may be required. Any potential sensitivities must be flagged to client, especially children's content. | H21: Censorship and / or softening of language for certain content may be required. Any potential sensitivities must be flagged to client, especially children's content. | I21: Censorship and / or softening of language for certain content may be required. Any potential sensitivities must be flagged to client, especially children's content. | J21: Censorship and / or softening of language for certain content may be required. Any potential sensitivities must be flagged to client, especially children's content. | K21: Censorship and / or softening of language for certain content may be required. Any potential sensitivities must be flagged to client, especially children's content. | L21: Censorship and / or softening of language for certain content may be required. Any potential sensitivities must be flagged to client, especially children's content. | M21: Censorship and / or softening of language for certain content may be required. Any potential sensitivities must be flagged to client, especially children's content. | N21: NA | O21: NA
C22: Translator's credit | D22: To be included on all subtitle files, unless client advises otherwise. | E22: To be included on all subtitle files, unless client advises otherwise. | F22: To be included on all subtitle files, unless client advises otherwise. | G22: To be included on all subtitle files, unless client advises otherwise. | H22: To be included on all subtitle files, unless client advises otherwise. | I22: To be included on all subtitle files, unless client advises otherwise. | J22: To be included on all subtitle files, unless client advises otherwise. | K22: To be included on all subtitle files, unless client advises otherwise. | L22: To be included on all subtitle files, unless client advises otherwise. | M22: To be included on all subtitle files, unless client advises otherwise. | N22: To be included on all subtitle files, unless client advises otherwise. | O22: To be included on all subtitle files, unless client advises otherwise.
B23: CLIENT APPROVAL | C23: Subtitles Approvals Non-Physical release | D23: Where client approvals are required, time for the approvals must be pre-agreed. If approvals are not received within agreed timelines, client is notified to determine next steps i.e extend deadline, proceed, etc | E23: Where client approvals are required, time for the approvals must be pre-agreed. If approvals are not received within agreed timelines, the timeline can be extended as appropriate and as agreed by both parties. | F23: Where client approvals are required, time for the approvals must be pre-agreed. If approvals are not received within agreed timelines, client is notified to determine next steps i.e extend deadline, proceed, etc | G23: Where client approvals are required, time for the approvals must be pre-agreed. If approvals are not received within agreed timelines, the timeline can be extended as appropriate and as agreed by both parties. | H23: No Client Approvals | I23: No Client Approvals | J23: Where client approvals are required, time for the approvals must be pre-agreed. If approvals are not received within agreed timelines, client is notified to determine next steps i.e extend deadline, proceed, etc | K23: Where client approvals are required, time for the approvals must be pre-agreed. If approvals are not received within agreed timelines, the timeline can be extended as appropriate and as agreed by both parties. Included in price. | L23: No Client Approvals | M23: No Client Approvals | N23: Client Approvals may be requested at no additional charge. | O23: Client Approvals may be requested at no additional charge.
C24: Subtitles Approvals Physical release | D24: Where client approvals are required, time for the approvals must be pre-agreed. If approvals are not received within agreed timelines, vendor notifies client to determine next steps i.e extend deadline, proceed, etc Included in price. All subs for Home Video release to be sent to the emulation QC vendor for pre-check before delivering to authoring. Pre-Delivery is done as XML with .BMP associated with content related media. | E24: Where client approvals are required, time for the approvals must be pre-agreed. If approvals are not received within agreed timelines, the timeline can be extended as appropriate and as agreed by both parties. Included in price. All subs for Home Video release to be sent to the emulation QC vendor for pre-check before delivering to authoring. Pre-Delivery is done as XML with .BMP associated with content related media. | F24: Where client approvals are required, time for the approvals must be pre-agreed. If approvals are not received within agreed timelines, vendor notifies client to determine next steps i.e extend deadline, proceed, etc Included in price. All subs for Home Video release to be sent to the emulation QC vendor for pre-check before delivering to authoring. Pre-Delivery is done as XML with .BMP associated with content related media. | G24: Where client approvals are required, time for the approvals must be pre-agreed. If approvals are not received within agreed timelines, the timeline can be extended as appropriate and as agreed by both parties. Included in price. All subs for Home Video release to be sent to the emulation QC vendor for pre-check before delivering to authoring. Pre-Delivery is done as XML with .BMP associated with content related media. | H24: No Client Approvals | I24: No Client Approvals | J24: Where client approvals are required, time for the approvals must be pre-agreed. If approvals are not received within agreed timelines, vendor notifies client to determine next steps i.e extend deadline, proceed, etc Included in price. | K24: Where client approvals are required, time for the approvals must be pre-agreed. If approvals are not received within agreed timelines, the timeline can be extended as appropriate and as agreed by both parties. Included in price. | L24: No Client Approvals | M24: No Client Approvals | N24: No Client Approvals | O24: No Client Approvals
B25: SONGS | C25: Songs Translation | D25: If plot pertinent, and has both been requested by client and confirmation lyrics have been cleared for translation. Additional charge. | E25: If plot pertinent, and has both been requested by client and confirmation lyrics have been cleared for translation. Additional charge. | F25: Plot pertinent and cleared lyrics will be subtitled If requested by Client | G25: Plot pertinent and cleared lyrics will be subtitled If requested by Client | H25: Plot pertinent and cleared lyrics will be subtitled If requested by Client | I25: Plot pertinent and cleared lyrics will be subtitled If requested by Client | J25: Plot pertinent and cleared lyrics will be subtitled If requested by Client | K25: Plot pertinent and cleared lyrics will be subtitled If requested by Client | L25: Plot pertinent and cleared lyrics will be subtitled If requested by Client | M25: Plot pertinent and cleared lyrics will be subtitled If requested by Client | N25: NA | O25: NA
B26: DELIVERABLES | C26: Format | D26: Includes one set of final deliverables to multiple end users, formats to be agreed with client. Maybe change "to be agreed" to "as currently agreed". Upload to 2/3 x endpoints? DETE/NEST/Keystone. HBO uploading to more than 2. Could have 1 format and 1 delivery with the assumption that in the future we will insource additional deliverables/endpoints in the future. | E26: Includes one set of final deliverables to multiple end users, formats to be agreed with client. | F26: Includes one set of final deliverables to multiple end users, formats to be agreed with client. | G26: Includes one set of final deliverables to multiple end users, formats to be agreed with client. | H26: Includes one set of final deliverables to multiple end users, formats to be agreed with client. | I26: Includes one set of final deliverables to multiple end users, formats to be agreed with client. | J26: Includes one set of final deliverables to multiple end users, formats to be agreed with client. | K26: Includes one set of final deliverables to multiple end users, formats to be agreed with client. | L26: Includes one set of final deliverables to multiple end users, formats to be agreed with client. | M26: Includes one set of final deliverables to multiple end users, formats to be agreed with client. | N26: Includes one set of final deliverables to multiple end users, formats to be agreed with client. | O26: Includes one set of final deliverables to multiple end users, formats to be agreed with client.
B27: ISSUES / REDELIVERIES | C27: Non-Physical release | D27: Vendor has an obligation to deliver accurate translated subtitle files, (this does not cover subjective difference). Egregious creative errors or technical errors must be remediated by vendor. | E27: Vendor has an obligation to deliver accurate translated subtitle files, (this does not cover subjective difference). Egregious creative errors or technical errors must be remediated by vendor. | F27: Vendor has an obligation to deliver accurate translated subtitle files, (this does not cover subjective difference). Egregious creative errors or technical errors must be remediated by vendor. | G27: Vendor has an obligation to deliver accurate translated subtitle files, (this does not cover subjective difference). Egregious creative errors or technical errors must be remediated by vendor. | H27: Vendor has an obligation to deliver accurate translated subtitle files, (this does not cover subjective difference). Egregious creative errors or technical errors must be remediated by vendor. | I27: Vendor has an obligation to deliver accurate translated subtitle files, (this does not cover subjective difference). Egregious creative errors or technical errors must be remediated by vendor. | J27: Vendor has an obligation to deliver accurate translated subtitle files, (this does not cover subjective difference). Egregious creative errors or technical errors must be remediated by vendor. | K27: Vendor has an obligation to deliver accurate translated subtitle files, (this does not cover subjective difference). Egregious creative errors or technical errors must be remediated by vendor. | L27: Vendor has an obligation to deliver accurate translated subtitle files, (this does not cover subjective difference). Egregious creative errors or technical errors must be remediated by vendor. | M27: Vendor has an obligation to deliver accurate translated subtitle files, (this does not cover subjective difference). Egregious creative errors or technical errors must be remediated by vendor. | N27: Vendor has an obligation to deliver accurate translated subtitle files, (this does not cover subjective difference). Egregious creative errors or technical errors must be remediated by vendor. | O27: Vendor has an obligation to deliver accurate translated subtitle files, (this does not cover subjective difference). Egregious creative errors or technical errors must be remediated by vendor.
C28: Physical release | D28: Upon receipt of QC report from 3rd party vendor, fixes will be redelivered within 48 hours. | E28: Upon receipt of QC report from 3rd party vendor, fixes will be redelivered within 48 hours. | F28: Upon receipt of QC report from 3rd party vendor, fixes will be redelivered within 48 hours. | G28: Upon receipt of QC report from 3rd party vendor, fixes will be redelivered within 48 hours. | H28: N/A | I28: N/A | J28: Upon receipt of QC report from 3rd party vendor, fixes will be redelivered within 48 hours. | K28: Upon receipt of QC report from 3rd party vendor, fixes will be redelivered within 48 hours. | L28: N/A | M28: N/A | N28: NA | O28: NA
B29: ARCHIVE/ BACK UP | C29: Additional deliverables | D29: Per WBD requirements. Additional charge may apply | E29: Per WBD requirements. Additional charge may apply | F29: Per WBD requirements. Additional charge may apply | G29: Per WBD requirements. Additional charge may apply | H29: Vendor Archive included | I29: Vendor Archive included | J29: Per WBD requirements. Additional charge may apply | K29: Per WBD requirements. Additional charge may apply | L29: Vendor Archive included | M29: Vendor Archive included | N29: Vendor Archive included | O29: Vendor Archive included
